Workbook
Name BoiDatas: OFFSET(Séries!$K$7,30-MAX(1,MIN(30,Informativo!$J$9)),0,MAX(1,MIN(30,Informativo!$J$9)),1)
Name BoiPrecos: OFFSET(Séries!$J$7,30-MAX(1,MIN(30,Informativo!$J$9)),0,MAX(1,MIN(30,Informativo!$J$9)),1)
Name DolarDatas: OFFSET(Séries!$O$7,30-MAX(1,MIN(30,Informativo!$J$10)),0,MAX(1,MIN(30,Informativo!$J$10)),1)
Name DolarPrecos: OFFSET(Séries!$N$7,30-MAX(1,MIN(30,Informativo!$J$10)),0,MAX(1,MIN(30,Informativo!$J$10)),1)
Name MilhoDatas: OFFSET(Séries!$G$7,30-MAX(1,MIN(30,Informativo!$J$8)),0,MAX(1,MIN(30,Informativo!$J$8)),1)
Name MilhoPrecos: OFFSET(Séries!$F$7,30-MAX(1,MIN(30,Informativo!$J$8)),0,MAX(1,MIN(30,Informativo!$J$8)),1)
Name SojaDatas: OFFSET(Séries!$C$7,30-MAX(1,MIN(30,Informativo!$J$7)),0,MAX(1,MIN(30,Informativo!$J$7)),1)
Name SojaPrecos: OFFSET(Séries!$B$7,30-MAX(1,MIN(30,Informativo!$J$7)),0,MAX(1,MIN(30,Informativo!$J$7)),1)

Sheet Informativo
A1: Informativo diário do agro
A2: Últimas cotações lançadas. Preços em reais; data da cotação indicada por produto.
A4: Preencher histórico | C4: Fontes e instruções | E4: CEPEA soja | G4: CEPEA milho | H4: CEPEA boi | I4: BCB dólar
A6: Produto | B6: Referência / unidade | C6: Data atual | D6: Preço atual | E6: Data anterior | F6: Preço anterior | G6: Variação R$ | H6: Variação % | I6: Desde o início | J6: Registros
A7: Soja | B7: Paranaguá / PR R$/sc 60 kg | C7: =IF(J7=0,"",_xlfn.MAXIFS(Histórico!$A$8:$A$1007,Histórico!$B$8:$B$1007,">0")) -> 46323 | D7: =IF(C7="","",INDEX(Histórico!$B$8:$B$1007,MATCH(C7,Histórico!$A$8:$A$1007,0))) -> 157.42 | E7: =IF(J7<2,"",_xlfn.MAXIFS(Histórico!$A$8:$A$1007,Histórico!$A$8:$A$1007,"<"&C7,Histórico!$B$8:$B$1007,">0")) -> 46322 | F7: =IF(OR(E7="",E7=0),"",INDEX(Histórico!$B$8:$B$1007,MATCH(E7,Histórico!$A$8:$A$1007,0))) -> 157.41 | G7: =IF(F7="","",D7-F7) -> 0.01 | H7: =IF(F7="","",D7/F7-1) -> 6.3528365e-05 | I7: =IF(J7<2,"",D7/INDEX(Histórico!$B$8:$B$1007,MATCH(_xlfn.MINIFS(Histórico!$A$8:$A$1007,Histórico!$A$8:$A$1007,">0",Histórico!$B$8:$B$1007,">0"),Histórico!$A$8:$A$1007,0))-1) -> -0.028391557 | J7: =COUNTIFS(Histórico!$A$8:$A$1007,">0",Histórico!$B$8:$B$1007,">0") -> 29
A8: Milho | B8: Campinas / SP R$/sc 60 kg | C8: =IF(J8=0,"",_xlfn.MAXIFS(Histórico!$A$8:$A$1007,Histórico!$C$8:$C$1007,">0")) -> 46323 | D8: =IF(C8="","",INDEX(Histórico!$C$8:$C$1007,MATCH(C8,Histórico!$A$8:$A$1007,0))) -> 64.73 | E8: =IF(J8<2,"",_xlfn.MAXIFS(Histórico!$A$8:$A$1007,Histórico!$A$8:$A$1007,"<"&C8,Histórico!$C$8:$C$1007,">0")) -> 46322 | F8: =IF(OR(E8="",E8=0),"",INDEX(Histórico!$C$8:$C$1007,MATCH(E8,Histórico!$A$8:$A$1007,0))) -> 64.87 | G8: =IF(F8="","",D8-F8) -> -0.14 | H8: =IF(F8="","",D8/F8-1) -> -0.0021581625 | I8: =IF(J8<2,"",D8/INDEX(Histórico!$C$8:$C$1007,MATCH(_xlfn.MINIFS(Histórico!$A$8:$A$1007,Histórico!$A$8:$A$1007,">0",Histórico!$C$8:$C$1007,">0"),Histórico!$A$8:$A$1007,0))-1) -> -0.065270758 | J8: =COUNTIFS(Histórico!$A$8:$A$1007,">0",Histórico!$C$8:$C$1007,">0") -> 29
A9: Boi gordo | B9: São Paulo R$/@ 15 kg | C9: =IF(J9=0,"",_xlfn.MAXIFS(Histórico!$A$8:$A$1007,Histórico!$D$8:$D$1007,">0")) -> 46323 | D9: =IF(C9="","",INDEX(Histórico!$D$8:$D$1007,MATCH(C9,Histórico!$A$8:$A$1007,0))) -> 389.05 | E9: =IF(J9<2,"",_xlfn.MAXIFS(Histórico!$A$8:$A$1007,Histórico!$A$8:$A$1007,"<"&C9,Histórico!$D$8:$D$1007,">0")) -> 46322 | F9: =IF(OR(E9="",E9=0),"",INDEX(Histórico!$D$8:$D$1007,MATCH(E9,Histórico!$A$8:$A$1007,0))) -> 386.3 | G9: =IF(F9="","",D9-F9) -> 2.75 | H9: =IF(F9="","",D9/F9-1) -> 0.0071188196 | I9: =IF(J9<2,"",D9/INDEX(Histórico!$D$8:$D$1007,MATCH(_xlfn.MINIFS(Histórico!$A$8:$A$1007,Histórico!$A$8:$A$1007,">0",Histórico!$D$8:$D$1007,">0"),Histórico!$A$8:$A$1007,0))-1) -> 0.10353141 | J9: =COUNTIFS(Histórico!$A$8:$A$1007,">0",Histórico!$D$8:$D$1007,">0") -> 29
A10: Dólar PTAX | B10: BCB / venda R$/US$ | C10: =IF(J10=0,"",_xlfn.MAXIFS(Histórico!$A$8:$A$1007,Histórico!$E$8:$E$1007,">0")) -> 46324 | D10: =IF(C10="","",INDEX(Histórico!$E$8:$E$1007,MATCH(C10,Histórico!$A$8:$A$1007,0))) -> 5.3744 | E10: =IF(J10<2,"",_xlfn.MAXIFS(Histórico!$A$8:$A$1007,Histórico!$A$8:$A$1007,"<"&C10,Histórico!$E$8:$E$1007,">0")) -> 46323 | F10: =IF(OR(E10="",E10=0),"",INDEX(Histórico!$E$8:$E$1007,MATCH(E10,Histórico!$A$8:$A$1007,0))) -> 5.342 | G10: =IF(F10="","",D10-F10) -> 0.0324 | H10: =IF(F10="","",D10/F10-1) -> 0.0060651441 | I10: =IF(J10<2,"",D10/INDEX(Histórico!$E$8:$E$1007,MATCH(_xlfn.MINIFS(Histórico!$A$8:$A$1007,Histórico!$A$8:$A$1007,">0",Histórico!$E$8:$E$1007,">0"),Histórico!$A$8:$A$1007,0))-1) -> 0.043147454 | J10: =COUNTIFS(Histórico!$A$8:$A$1007,">0",Histórico!$E$8:$E$1007,">0") -> 30
A12: Variação = preço atual ÷ cotação anterior disponível − 1. “Desde o início” usa a primeira cotação de cada série.
A13: Células amarelas no Histórico: preenchimento manual. Fórmulas e gráficos se atualizam ao lançar novos valores.
A14: =IF(COUNTIF(Histórico!$K$8:$K$1007,"?*")>0,"Revise as linhas sinalizadas na coluna Conferência do Histórico.","Gráficos: até 30 cotações válidas por produto, em ordem de data.") -> Gráficos: até 30 cotações válidas por produto, em ordem de data.
A50: Histórico inicial: 17 a 25/09/2026. Fontes: CEPEA/ESALQ e BCB, reproduzidos por Notícias Agrícolas.
A51: Consulta inicial em 28/09/2026. Atualização dos preços é manual. PTAX é a taxa de referência de venda do BCB.
A52: Dias sem preço são omitidos dos gráficos; a linha conecta as observações disponíveis. Todas as fontes estão na aba Fontes e guia.

Sheet Histórico
A1: Histórico de cotações
A2: Preencha uma linha por data, da mais antiga à mais recente. Use a data publicada na fonte.
A3: Edite as células amarelas (A:E e J). Deixe em branco os produtos sem cotação no dia. Não digite zero, R$ ou traços.
A4: Soja / CEPEA | C4: Milho / CEPEA | E4: Boi / CEPEA | G4: Dólar / BCB | J4: Fontes e guia
A5: Preparado para 1.000 datas, até a linha 1007. Complete a mesma linha quando surgir outra cotação daquela data.
A6: Variações em % calculadas sobre a cotação anterior disponível de cada produto. Valores iniciais: fontes S1 a S4.
A7: Data da cotação | B7: Soja R$/sc 60 kg | C7: Milho R$/sc 60 kg | D7: Boi gordo R$/@ 15 kg | E7: Dólar PTAX R$/US$ venda | F7: Soja variação % | G7: Milho variação % | H7: Boi gordo variação % | I7: Dólar variação % | J7: Observações / fonte | K7: Conferência
A8: 46282 | B8: 162.02 | C8: 69.25 | D8: 352.55 | E8: 5.1521 | F8: ="" | G8: ="" | H8: ="" | I8: ="" | J8: Fontes S1–S4; consulta 28/09/2026 | K8: =IF(COUNTA(A8:E8)=0,"",IF(A8="","Preencha a data",IF(NOT(ISNUMBER(A8)),"Data inválida",IF(OR(A8<36526,A8>73050,A8<>INT(A8)),"Data inválida",IF(FALSE,"Data repetida / fora de ordem",IF(COUNTA(B8:E8)<>COUNT(B8:E8),"Use preços numéricos",IF(OR(AND(ISNUMBER(B8),B8<=0),AND(ISNUMBER(C8),C8<=0),AND(ISNUMBER(D8),D8<=0),AND(ISNUMBER(E8),E8<=0)),"Use preços positivos","")))))))
A9: 46283 | B9: 161.89 | C9: 69.29 | D9: 352.9 | E9: 5.1575 | F9: =IF(OR($A9="",B9="",B9<=0,Séries!Q8=""),"",B9/Séries!Q8-1) -> -0.00080237008 | G9: =IF(OR($A9="",C9="",C9<=0,Séries!R8=""),"",C9/Séries!R8-1) -> 0.00057761733 | H9: =IF(OR($A9="",D9="",D9<=0,Séries!S8=""),"",D9/Séries!S8-1) -> 0.00099276698 | I9: =IF(OR($A9="",E9="",E9<=0,Séries!T8=""),"",E9/Séries!T8-1) -> 0.0010481163 | J9: Fontes S1–S4; consulta 28/09/2026 | K9: =IF(COUNTA(A9:E9)=0,"",IF(A9="","Preencha a data",IF(NOT(ISNUMBER(A9)),"Data inválida",IF(OR(A9<36526,A9>73050,A9<>INT(A9)),"Data inválida",IF(A9<=Séries!U8,"Data repetida / fora de ordem",IF(COUNTA(B9:E9)<>COUNT(B9:E9),"Use preços numéricos",IF(OR(AND(ISNUMBER(B9),B9<=0),AND(ISNUMBER(C9),C9<=0),AND(ISNUMBER(D9),D9<=0),AND(ISNUMBER(E9),E9<=0)),"Use preços positivos","")))))))
A10: 46286 | B10: 161.52 | C10: 69.62 | D10: 354.65 | E10: 5.1117 | F10: =IF(OR($A10="",B10="",B10<=0,Séries!Q9=""),"",B10/Séries!Q9-1) -> -0.0022855025 | G10: =IF(OR($A10="",C10="",C10<=0,Séries!R9=""),"",C10/Séries!R9-1) -> 0.004762592 | H10: =IF(OR($A10="",D10="",D10<=0,Séries!S9=""),"",D10/Séries!S9-1) -> 0.0049589119 | I10: =IF(OR($A10="",E10="",E10<=0,Séries!T9=""),"",E10/Séries!T9-1) -> -0.0088802714 | J10: Fontes S1–S4; consulta 28/09/2026 | K10: =IF(COUNTA(A10:E10)=0,"",IF(A10="","Preencha a data",IF(NOT(ISNUMBER(A10)),"Data inválida",IF(OR(A10<36526,A10>73050,A10<>INT(A10)),"Data inválida",IF(A10<=Séries!U9,"Data repetida / fora de ordem",IF(COUNTA(B10:E10)<>COUNT(B10:E10),"Use preços numéricos",IF(OR(AND(ISNUMBER(B10),B10<=0),AND(ISNUMBER(C10),C10<=0),AND(ISNUMBER(D10),D10<=0),AND(ISNUMBER(E10),E10<=0)),"Use preços positivos","")))))))
A11: 46287 | B11: 161.93 | C11: 69.74 | D11: 356.1 | E11: 5.1161 | F11: =IF(OR($A11="",B11="",B11<=0,Séries!Q10=""),"",B11/Séries!Q10-1) -> 0.0025383853 | G11: =IF(OR($A11="",C11="",C11<=0,Séries!R10=""),"",C11/Séries!R10-1) -> 0.0017236426 | H11: =IF(OR($A11="",D11="",D11<=0,Séries!S10=""),"",D11/Séries!S10-1) -> 0.004088538 | I11: =IF(OR($A11="",E11="",E11<=0,Séries!T10=""),"",E11/Séries!T10-1) -> 0.00086077039 | J11: Fontes S1–S4; consulta 28/09/2026 | K11: =IF(COUNTA(A11:E11)=0,"",IF(A11="","Preencha a data",IF(NOT(ISNUMBER(A11)),"Data inválida",IF(OR(A11<36526,A11>73050,A11<>INT(A11)),"Data inválida",IF(A11<=Séries!U10,"Data repetida / fora de ordem",IF(COUNTA(B11:E11)<>COUNT(B11:E11),"Use preços numéricos",IF(OR(AND(ISNUMBER(B11),B11<=0),AND(ISNUMBER(C11),C11<=0),AND(ISNUMBER(D11),D11<=0),AND(ISNUMBER(E11),E11<=0)),"Use preços positivos","")))))))
A12: 46288 | B12: 161.65 | C12: 69.82 | D12: 357.4 | E12: 5.1414 | F12: =IF(OR($A12="",B12="",B12<=0,Séries!Q11=""),"",B12/Séries!Q11-1) -> -0.0017291422 | G12: =IF(OR($A12="",C12="",C12<=0,Séries!R11=""),"",C12/Séries!R11-1) -> 0.0011471179 | H12: =IF(OR($A12="",D12="",D12<=0,Séries!S11=""),"",D12/Séries!S11-1) -> 0.0036506599 | I12: =IF(OR($A12="",E12="",E12<=0,Séries!T11=""),"",E12/Séries!T11-1) -> 0.0049451731 | J12: Fontes S1–S4; consulta 28/09/2026 | K12: =IF(COUNTA(A12:E12)=0,"",IF(A12="","Preencha a data",IF(NOT(ISNUMBER(A12)),"Data inválida",IF(OR(A12<36526,A12>73050,A12<>INT(A12)),"Data inválida",IF(A12<=Séries!U11,"Data repetida / fora de ordem",IF(COUNTA(B12:E12)<>COUNT(B12:E12),"Use preços numéricos",IF(OR(AND(ISNUMBER(B12),B12<=0),AND(ISNUMBER(C12),C12<=0),AND(ISNUMBER(D12),D12<=0),AND(ISNUMBER(E12),E12<=0)),"Use preços positivos","")))))))
A13: 46289 | B13: 161.84 | C13: 69.81 | D13: 358.2 | E13: 5.1795 | F13: =IF(OR($A13="",B13="",B13<=0,Séries!Q12=""),"",B13/Séries!Q12-1) -> 0.0011753789 | G13: =IF(OR($A13="",C13="",C13<=0,Séries!R12=""),"",C13/Séries!R12-1) -> -0.00014322544 | H13: =IF(OR($A13="",D13="",D13<=0,Séries!S12=""),"",D13/Séries!S12-1) -> 0.0022383884 | I13: =IF(OR($A13="",E13="",E13<=0,Séries!T12=""),"",E13/Séries!T12-1) -> 0.007410433 | J13: Fontes S1–S4; consulta 28/09/2026 | K13: =IF(COUNTA(A13:E13)=0,"",IF(A13="","Preencha a data",IF(NOT(ISNUMBER(A13)),"Data inválida",IF(OR(A13<36526,A13>73050,A13<>INT(A13)),"Data inválida",IF(A13<=Séries!U12,"Data repetida / fora de ordem",IF(COUNTA(B13:E13)<>COUNT(B13:E13),"Use preços numéricos",IF(OR(AND(ISNUMBER(B13),B13<=0),AND(ISNUMBER(C13),C13<=0),AND(ISNUMBER(D13),D13<=0),AND(ISNUMBER(E13),E13<=0)),"Use preços positivos","")))))))
A14: 46290 | B14: 161 | C14: 69.65 | D14: 358.8 | E14: 5.1991 | F14: =IF(OR($A14="",B14="",B14<=0,Séries!Q13=""),"",B14/Séries!Q13-1) -> -0.0051903114 | G14: =IF(OR($A14="",C14="",C14<=0,Séries!R13=""),"",C14/Séries!R13-1) -> -0.0022919353 | H14: =IF(OR($A14="",D14="",D14<=0,Séries!S13=""),"",D14/Séries!S13-1) -> 0.0016750419 | I14: =IF(OR($A14="",E14="",E14<=0,Séries!T13=""),"",E14/Séries!T13-1) -> 0.003784149 | J14: Fontes S1–S4; consulta 28/09/2026 | K14: =IF(COUNTA(A14:E14)=0,"",IF(A14="","Preencha a data",IF(NOT(ISNUMBER(A14)),"Data inválida",IF(OR(A14<36526,A14>73050,A14<>INT(A14)),"Data inválida",IF(A14<=Séries!U13,"Data repetida / fora de ordem",IF(COUNTA(B14:E14)<>COUNT(B14:E14),"Use preços numéricos",IF(OR(AND(ISNUMBER(B14),B14<=0),AND(ISNUMBER(C14),C14<=0),AND(ISNUMBER(D14),D14<=0),AND(ISNUMBER(E14),E14<=0)),"Use preços positivos","")))))))
A15: 46293 | B15: 160.43 | C15: 69.48 | D15: 359.95 | E15: 5.2132 | F15: =IF(OR($A15="",B15="",B15<=0,Séries!Q14=""),"",B15/Séries!Q14-1) -> -0.0035403727 | G15: =IF(OR($A15="",C15="",C15<=0,Séries!R14=""),"",C15/Séries!R14-1) -> -0.0024407753 | H15: =IF(OR($A15="",D15="",D15<=0,Séries!S14=""),"",D15/Séries!S14-1) -> 0.0032051282 | I15: =IF(OR($A15="",E15="",E15<=0,Séries!T14=""),"",E15/Séries!T14-1) -> 0.0027120078 | J15: CEPEA/ESALQ via Notícias Agrícolas (S1–S3); PTAX venda BCB/Olinda (S4); corrigido: dólar era 5.22; consulta 28/10/2026 | K15: =IF(COUNTA(A15:E15)=0,"",IF(A15="","Preencha a data",IF(NOT(ISNUMBER(A15)),"Data inválida",IF(OR(A15<36526,A15>73050,A15<>INT(A15)),"Data inválida",IF(A15<=Séries!U14,"Data repetida / fora de ordem",IF(COUNTA(B15:E15)<>COUNT(B15:E15),"Use preços numéricos",IF(OR(AND(ISNUMBER(B15),B15<=0),AND(ISNUMBER(C15),C15<=0),AND(ISNUMBER(D15),D15<=0),AND(ISNUMBER(E15),E15<=0)),"Use preços positivos","")))))))
A16: 46294 | B16: 161.27 | C16: 69.2 | D16: 363.05 | E16: 5.2204 | F16: =IF(OR($A16="",B16="",B16<=0,Séries!Q15=""),"",B16/Séries!Q15-1) -> 0.0052359284 | G16: =IF(OR($A16="",C16="",C16<=0,Séries!R15=""),"",C16/Séries!R15-1) -> -0.0040299367 | H16: =IF(OR($A16="",D16="",D16<=0,Séries!S15=""),"",D16/Séries!S15-1) -> 0.0086123073 | I16: =IF(OR($A16="",E16="",E16<=0,Séries!T15=""),"",E16/Séries!T15-1) -> 0.0013811095 | J16: CEPEA/ESALQ via Notícias Agrícolas (S1–S3); PTAX venda BCB/Olinda (S4); corrigido: dólar era 5.2166; consulta 28/10/2026 | K16: =IF(COUNTA(A16:E16)=0,"",IF(A16="","Preencha a data",IF(NOT(ISNUMBER(A16)),"Data inválida",IF(OR(A16<36526,A16>73050,A16<>INT(A16)),"Data inválida",IF(A16<=Séries!U15,"Data repetida / fora de ordem",IF(COUNTA(B16:E16)<>COUNT(B16:E16),"Use preços numéricos",IF(OR(AND(ISNUMBER(B16),B16<=0),AND(ISNUMBER(C16),C16<=0),AND(ISNUMBER(D16),D16<=0),AND(ISNUMBER(E16),E16<=0)),"Use preços positivos","")))))))
A17: 46295 | B17: 161.56 | C17: 68.67 | D17: 364.3 | E17: 5.1809 | F17: =IF(OR($A17="",B17="",B17<=0,Séries!Q16=""),"",B17/Séries!Q16-1) -> 0.0017982266 | G17: =IF(OR($A17="",C17="",C17<=0,Séries!R16=""),"",C17/Séries!R16-1) -> -0.0076589595 | H17: =IF(OR($A17="",D17="",D17<=0,Séries!S16=""),"",D17/Séries!S16-1) -> 0.0034430519 | I17: =IF(OR($A17="",E17="",E17<=0,Séries!T16=""),"",E17/Séries!T16-1) -> -0.00756647 | J17: CEPEA/ESALQ via Notícias Agrícolas (S1–S3); PTAX venda BCB/Olinda (S4); corrigido: dólar era 5.1743; consulta 28/10/2026 | K17: =IF(COUNTA(A17:E17)=0,"",IF(A17="","Preencha a data",IF(NOT(ISNUMBER(A17)),"Data inválida",IF(OR(A17<36526,A17>73050,A17<>INT(A17)),"Data inválida",IF(A17<=Séries!U16,"Data repetida / fora de ordem",IF(COUNTA(B17:E17)<>COUNT(B17:E17),"Use preços numéricos",IF(OR(AND(ISNUMBER(B17),B17<=0),AND(ISNUMBER(C17),C17<=0),AND(ISNUMBER(D17),D17<=0),AND(ISNUMBER(E17),E17<=0)),"Use preços positivos","")))))))
A18: 46296 | B18: 160.9 | C18: 68.58 | D18: 366.5 | E18: 5.2079 | F18: =IF(OR($A18="",B18="",B18<=0,Séries!Q17=""),"",B18/Séries!Q17-1) -> -0.0040851696 | G18: =IF(OR($A18="",C18="",C18<=0,Séries!R17=""),"",C18/Séries!R17-1) -> -0.001310616 | H18: =IF(OR($A18="",D18="",D18<=0,Séries!S17=""),"",D18/Séries!S17-1) -> 0.0060389789 | I18: =IF(OR($A18="",E18="",E18<=0,Séries!T17=""),"",E18/Séries!T17-1) -> 0.0052114497 | J18: CEPEA/ESALQ via Notícias Agrícolas (S1–S3); PTAX venda BCB/Olinda (S4); corrigido: dólar era 5.2073; consulta 28/10/2026 | K18: =IF(COUNTA(A18:E18)=0,"",IF(A18="","Preencha a data",IF(NOT(ISNUMBER(A18)),"Data inválida",IF(OR(A18<36526,A18>73050,A18<>INT(A18)),"Data inválida",IF(A18<=Séries!U17,"Data repetida / fora de ordem",IF(COUNTA(B18:E18)<>COUNT(B18:E18),"Use preços numéricos",IF(OR(AND(ISNUMBER(B18),B18<=0),AND(ISNUMBER(C18),C18<=0),AND(ISNUMBER(D18),D18<=0),AND(ISNUMBER(E18),E18<=0)),"Use preços positivos","")))))))
A19: 46297 | B19: 159.94 | C19: 68.53 | D19: 369.9 | E19: 5.2238 | F19: =IF(OR($A19="",B19="",B19<=0,Séries!Q18=""),"",B19/Séries!Q18-1) -> -0.0059664388 | G19: =IF(OR($A19="",C19="",C19<=0,Séries!R18=""),"",C19/Séries!R18-1) -> -0.00072907553 | H19: =IF(OR($A19="",D19="",D19<=0,Séries!S18=""),"",D19/Séries!S18-1) -> 0.0092769441 | I19: =IF(OR($A19="",E19="",E19<=0,Séries!T18=""),"",E19/Séries!T18-1) -> 0.003053054 | J19: CEPEA/ESALQ via Notícias Agrícolas (S1–S3); PTAX venda BCB/Olinda (S4); corrigido: dólar era 5.2232; consulta 28/10/2026 | K19: =IF(COUNTA(A19:E19)=0,"",IF(A19="","Preencha a data",IF(NOT(ISNUMBER(A19)),"Data inválida",IF(OR(A19<36526,A19>73050,A19<>INT(A19)),"Data inválida",IF(A19<=Séries!U18,"Data repetida / fora de ordem",IF(COUNTA(B19:E19)<>COUNT(B19:E19),"Use preços numéricos",IF(OR(AND(ISNUMBER(B19),B19<=0),AND(ISNUMBER(C19),C19<=0),AND(ISNUMBER(D19),D19<=0),AND(ISNUMBER(E19),E19<=0)),"Use preços positivos","")))))))
A20: 46300 | B20: 158.09 | C20: 67.26 | D20: 372.95 | E20: 4.9859 | F20: =IF(OR($A20="",B20="",B20<=0,Séries!Q19=""),"",B20/Séries!Q19-1) -> -0.011566838 | G20: =IF(OR($A20="",C20="",C20<=0,Séries!R19=""),"",C20/Séries!R19-1) -> -0.01853203 | H20: =IF(OR($A20="",D20="",D20<=0,Séries!S19=""),"",D20/Séries!S19-1) -> 0.0082454717 | I20: =IF(OR($A20="",E20="",E20<=0,Séries!T19=""),"",E20/Séries!T19-1) -> -0.04554156 | J20: CEPEA/ESALQ via Notícias Agrícolas (S1–S3); PTAX venda BCB/Olinda (S4); corrigido: dólar era 4.9853; consulta 28/10/2026 | K20: =IF(COUNTA(A20:E20)=0,"",IF(A20="","Preencha a data",IF(NOT(ISNUMBER(A20)),"Data inválida",IF(OR(A20<36526,A20>73050,A20<>INT(A20)),"Data inválida",IF(A20<=Séries!U19,"Data repetida / fora de ordem",IF(COUNTA(B20:E20)<>COUNT(B20:E20),"Use preços numéricos",IF(OR(AND(ISNUMBER(B20),B20<=0),AND(ISNUMBER(C20),C20<=0),AND(ISNUMBER(D20),D20<=0),AND(ISNUMBER(E20),E20<=0)),"Use preços positivos","")))))))
... A36: 46323 | B36: 157.42 | C36: 64.73 | D36: 389.05 | E36: 5.342 | F36: =IF(OR($A36="",B36="",B36<=0,Séries!Q35=""),"",B36/Séries!Q35-1) -> 6.3528365e-05 | G36: =IF(OR($A36="",C36="",C36<=0,Séries!R35=""),"",C36/Séries!R35-1) -> -0.0021581625 | H36: =IF(OR($A36="",D36="",D36<=0,Séries!S35=""),"",D36/Séries!S35-1) -> 0.0071188196 | I36: =IF(OR($A36="",E36="",E36<=0,Séries!T35=""),"",E36/Séries!T35-1) -> 0.0013871705 | J36: CEPEA/ESALQ via Notícias Agrícolas (S1–S3); PTAX venda BCB/Olinda (S4); consulta 28/10/2026 | K36: =IF(COUNTA(A36:E36)=0,"",IF(A36="","Preencha a data",IF(NOT(ISNUMBER(A36)),"Data inválida",IF(OR(A36<36526,A36>73050,A36<>INT(A36)),"Data inválida",IF(A36<=Séries!U35,"Data repetida / fora de ordem",IF(COUNTA(B36:E36)<>COUNT(B36:E36),"Use preços numéricos",IF(OR(AND(ISNUMBER(B36),B36<=0),AND(ISNUMBER(C36),C36<=0),AND(ISNUMBER(D36),D36<=0),AND(ISNUMBER(E36),E36<=0)),"Use preços positivos","")))))))
A37: 46324 | E37: 5.3744 | F37: =IF(OR($A37="",B37="",B37<=0,Séries!Q36=""),"",B37/Séries!Q36-1) | G37: =IF(OR($A37="",C37="",C37<=0,Séries!R36=""),"",C37/Séries!R36-1) | H37: =IF(OR($A37="",D37="",D37<=0,Séries!S36=""),"",D37/Séries!S36-1) | I37: =IF(OR($A37="",E37="",E37<=0,Séries!T36=""),"",E37/Séries!T36-1) -> 0.0060651441 | J37: PTAX venda BCB/Olinda (S4); pendente: soja, milho, boi; consulta 29/10/2026 | K37: =IF(COUNTA(A37:E37)=0,"",IF(A37="","Preencha a data",IF(NOT(ISNUMBER(A37)),"Data inválida",IF(OR(A37<36526,A37>73050,A37<>INT(A37)),"Data inválida",IF(A37<=Séries!U36,"Data repetida / fora de ordem",IF(COUNTA(B37:E37)<>COUNT(B37:E37),"Use preços numéricos",IF(OR(AND(ISNUMBER(B37),B37<=0),AND(ISNUMBER(C37),C37<=0),AND(ISNUMBER(D37),D37<=0),AND(ISNUMBER(E37),E37<=0)),"Use preços positivos","")))))))
F38: =IF(OR($A38="",B38="",B38<=0,Séries!Q37=""),"",B38/Séries!Q37-1) | G38: =IF(OR($A38="",C38="",C38<=0,Séries!R37=""),"",C38/Séries!R37-1) | H38: =IF(OR($A38="",D38="",D38<=0,Séries!S37=""),"",D38/Séries!S37-1) | I38: =IF(OR($A38="",E38="",E38<=0,Séries!T37=""),"",E38/Séries!T37-1) | K38: =IF(COUNTA(A38:E38)=0,"",IF(A38="","Preencha a data",IF(NOT(ISNUMBER(A38)),"Data inválida",IF(OR(A38<36526,A38>73050,A38<>INT(A38)),"Data inválida",IF(A38<=Séries!U37,"Data repetida / fora de ordem",IF(COUNTA(B38:E38)<>COUNT(B38:E38),"Use preços numéricos",IF(OR(AND(ISNUMBER(B38),B38<=0),AND(ISNUMBER(C38),C38<=0),AND(ISNUMBER(D38),D38<=0),AND(ISNUMBER(E38),E38<=0)),"Use preços positivos","")))))))
F39: =IF(OR($A39="",B39="",B39<=0,Séries!Q38=""),"",B39/Séries!Q38-1) | G39: =IF(OR($A39="",C39="",C39<=0,Séries!R38=""),"",C39/Séries!R38-1) | H39: =IF(OR($A39="",D39="",D39<=0,Séries!S38=""),"",D39/Séries!S38-1) | I39: =IF(OR($A39="",E39="",E39<=0,Séries!T38=""),"",E39/Séries!T38-1) | K39: =IF(COUNTA(A39:E39)=0,"",IF(A39="","Preencha a data",IF(NOT(ISNUMBER(A39)),"Data inválida",IF(OR(A39<36526,A39>73050,A39<>INT(A39)),"Data inválida",IF(A39<=Séries!U38,"Data repetida / fora de ordem",IF(COUNTA(B39:E39)<>COUNT(B39:E39),"Use preços numéricos",IF(OR(AND(ISNUMBER(B39),B39<=0),AND(ISNUMBER(C39),C39<=0),AND(ISNUMBER(D39),D39<=0),AND(ISNUMBER(E39),E39<=0)),"Use preços positivos","")))))))
F40: =IF(OR($A40="",B40="",B40<=0,Séries!Q39=""),"",B40/Séries!Q39-1) | G40: =IF(OR($A40="",C40="",C40<=0,Séries!R39=""),"",C40/Séries!R39-1) | H40: =IF(OR($A40="",D40="",D40<=0,Séries!S39=""),"",D40/Séries!S39-1) | I40: =IF(OR($A40="",E40="",E40<=0,Séries!T39=""),"",E40/Séries!T39-1) | K40: =IF(COUNTA(A40:E40)=0,"",IF(A40="","Preencha a data",IF(NOT(ISNUMBER(A40)),"Data inválida",IF(OR(A40<36526,A40>73050,A40<>INT(A40)),"Data inválida",IF(A40<=Séries!U39,"Data repetida / fora de ordem",IF(COUNTA(B40:E40)<>COUNT(B40:E40),"Use preços numéricos",IF(OR(AND(ISNUMBER(B40),B40<=0),AND(ISNUMBER(C40),C40<=0),AND(ISNUMBER(D40),D40<=0),AND(ISNUMBER(E40),E40<=0)),"Use preços positivos","")))))))
F41: =IF(OR($A41="",B41="",B41<=0,Séries!Q40=""),"",B41/Séries!Q40-1) | G41: =IF(OR($A41="",C41="",C41<=0,Séries!R40=""),"",C41/Séries!R40-1) | H41: =IF(OR($A41="",D41="",D41<=0,Séries!S40=""),"",D41/Séries!S40-1) | I41: =IF(OR($A41="",E41="",E41<=0,Séries!T40=""),"",E41/Séries!T40-1) | K41: =IF(COUNTA(A41:E41)=0,"",IF(A41="","Preencha a data",IF(NOT(ISNUMBER(A41)),"Data inválida",IF(OR(A41<36526,A41>73050,A41<>INT(A41)),"Data inválida",IF(A41<=Séries!U40,"Data repetida / fora de ordem",IF(COUNTA(B41:E41)<>COUNT(B41:E41),"Use preços numéricos",IF(OR(AND(ISNUMBER(B41),B41<=0),AND(ISNUMBER(C41),C41<=0),AND(ISNUMBER(D41),D41<=0),AND(ISNUMBER(E41),E41<=0)),"Use preços positivos","")))))))
F42: =IF(OR($A42="",B42="",B42<=0,Séries!Q41=""),"",B42/Séries!Q41-1) | G42: =IF(OR($A42="",C42="",C42<=0,Séries!R41=""),"",C42/Séries!R41-1) | H42: =IF(OR($A42="",D42="",D42<=0,Séries!S41=""),"",D42/Séries!S41-1) | I42: =IF(OR($A42="",E42="",E42<=0,Séries!T41=""),"",E42/Séries!T41-1) | K42: =IF(COUNTA(A42:E42)=0,"",IF(A42="","Preencha a data",IF(NOT(ISNUMBER(A42)),"Data inválida",IF(OR(A42<36526,A42>73050,A42<>INT(A42)),"Data inválida",IF(A42<=Séries!U41,"Data repetida / fora de ordem",IF(COUNTA(B42:E42)<>COUNT(B42:E42),"Use preços numéricos",IF(OR(AND(ISNUMBER(B42),B42<=0),AND(ISNUMBER(C42),C42<=0),AND(ISNUMBER(D42),D42<=0),AND(ISNUMBER(E42),E42<=0)),"Use preços positivos","")))))))
F43: =IF(OR($A43="",B43="",B43<=0,Séries!Q42=""),"",B43/Séries!Q42-1) | G43: =IF(OR($A43="",C43="",C43<=0,Séries!R42=""),"",C43/Séries!R42-1) | H43: =IF(OR($A43="",D43="",D43<=0,Séries!S42=""),"",D43/Séries!S42-1) | I43: =IF(OR($A43="",E43="",E43<=0,Séries!T42=""),"",E43/Séries!T42-1) | K43: =IF(COUNTA(A43:E43)=0,"",IF(A43="","Preencha a data",IF(NOT(ISNUMBER(A43)),"Data inválida",IF(OR(A43<36526,A43>73050,A43<>INT(A43)),"Data inválida",IF(A43<=Séries!U42,"Data repetida / fora de ordem",IF(COUNTA(B43:E43)<>COUNT(B43:E43),"Use preços numéricos",IF(OR(AND(ISNUMBER(B43),B43<=0),AND(ISNUMBER(C43),C43<=0),AND(ISNUMBER(D43),D43<=0),AND(ISNUMBER(E43),E43<=0)),"Use preços positivos","")))))))
F44: =IF(OR($A44="",B44="",B44<=0,Séries!Q43=""),"",B44/Séries!Q43-1) | G44: =IF(OR($A44="",C44="",C44<=0,Séries!R43=""),"",C44/Séries!R43-1) | H44: =IF(OR($A44="",D44="",D44<=0,Séries!S43=""),"",D44/Séries!S43-1) | I44: =IF(OR($A44="",E44="",E44<=0,Séries!T43=""),"",E44/Séries!T43-1) | K44: =IF(COUNTA(A44:E44)=0,"",IF(A44="","Preencha a data",IF(NOT(ISNUMBER(A44)),"Data inválida",IF(OR(A44<36526,A44>73050,A44<>INT(A44)),"Data inválida",IF(A44<=Séries!U43,"Data repetida / fora de ordem",IF(COUNTA(B44:E44)<>COUNT(B44:E44),"Use preços numéricos",IF(OR(AND(ISNUMBER(B44),B44<=0),AND(ISNUMBER(C44),C44<=0),AND(ISNUMBER(D44),D44<=0),AND(ISNUMBER(E44),E44<=0)),"Use preços positivos","")))))))
F45: =IF(OR($A45="",B45="",B45<=0,Séries!Q44=""),"",B45/Séries!Q44-1) | G45: =IF(OR($A45="",C45="",C45<=0,Séries!R44=""),"",C45/Séries!R44-1) | H45: =IF(OR($A45="",D45="",D45<=0,Séries!S44=""),"",D45/Séries!S44-1) | I45: =IF(OR($A45="",E45="",E45<=0,Séries!T44=""),"",E45/Séries!T44-1) | K45: =IF(COUNTA(A45:E45)=0,"",IF(A45="","Preencha a data",IF(NOT(ISNUMBER(A45)),"Data inválida",IF(OR(A45<36526,A45>73050,A45<>INT(A45)),"Data inválida",IF(A45<=Séries!U44,"Data repetida / fora de ordem",IF(COUNTA(B45:E45)<>COUNT(B45:E45),"Use preços numéricos",IF(OR(AND(ISNUMBER(B45),B45<=0),AND(ISNUMBER(C45),C45<=0),AND(ISNUMBER(D45),D45<=0),AND(ISNUMBER(E45),E45<=0)),"Use preços positivos","")))))))
F46: =IF(OR($A46="",B46="",B46<=0,Séries!Q45=""),"",B46/Séries!Q45-1) | G46: =IF(OR($A46="",C46="",C46<=0,Séries!R45=""),"",C46/Séries!R45-1) | H46: =IF(OR($A46="",D46="",D46<=0,Séries!S45=""),"",D46/Séries!S45-1) | I46: =IF(OR($A46="",E46="",E46<=0,Séries!T45=""),"",E46/Séries!T45-1) | K46: =IF(COUNTA(A46:E46)=0,"",IF(A46="","Preencha a data",IF(NOT(ISNUMBER(A46)),"Data inválida",IF(OR(A46<36526,A46>73050,A46<>INT(A46)),"Data inválida",IF(A46<=Séries!U45,"Data repetida / fora de ordem",IF(COUNTA(B46:E46)<>COUNT(B46:E46),"Use preços numéricos",IF(OR(AND(ISNUMBER(B46),B46<=0),AND(ISNUMBER(C46),C46<=0),AND(ISNUMBER(D46),D46<=0),AND(ISNUMBER(E46),E46<=0)),"Use preços positivos","")))))))
F47: =IF(OR($A47="",B47="",B47<=0,Séries!Q46=""),"",B47/Séries!Q46-1) | G47: =IF(OR($A47="",C47="",C47<=0,Séries!R46=""),"",C47/Séries!R46-1) | H47: =IF(OR($A47="",D47="",D47<=0,Séries!S46=""),"",D47/Séries!S46-1) | I47: =IF(OR($A47="",E47="",E47<=0,Séries!T46=""),"",E47/Séries!T46-1) | K47: =IF(COUNTA(A47:E47)=0,"",IF(A47="","Preencha a data",IF(NOT(ISNUMBER(A47)),"Data inválida",IF(OR(A47<36526,A47>73050,A47<>INT(A47)),"Data inválida",IF(A47<=Séries!U46,"Data repetida / fora de ordem",IF(COUNTA(B47:E47)<>COUNT(B47:E47),"Use preços numéricos",IF(OR(AND(ISNUMBER(B47),B47<=0),AND(ISNUMBER(C47),C47<=0),AND(ISNUMBER(D47),D47<=0),AND(ISNUMBER(E47),E47<=0)),"Use preços positivos","")))))))
F48: =IF(OR($A48="",B48="",B48<=0,Séries!Q47=""),"",B48/Séries!Q47-1) | G48: =IF(OR($A48="",C48="",C48<=0,Séries!R47=""),"",C48/Séries!R47-1) | H48: =IF(OR($A48="",D48="",D48<=0,Séries!S47=""),"",D48/Séries!S47-1) | I48: =IF(OR($A48="",E48="",E48<=0,Séries!T47=""),"",E48/Séries!T47-1) | K48: =IF(COUNTA(A48:E48)=0,"",IF(A48="","Preencha a data",IF(NOT(ISNUMBER(A48)),"Data inválida",IF(OR(A48<36526,A48>73050,A48<>INT(A48)),"Data inválida",IF(A48<=Séries!U47,"Data repetida / fora de ordem",IF(COUNTA(B48:E48)<>COUNT(B48:E48),"Use preços numéricos",IF(OR(AND(ISNUMBER(B48),B48<=0),AND(ISNUMBER(C48),C48<=0),AND(ISNUMBER(D48),D48<=0),AND(ISNUMBER(E48),E48<=0)),"Use preços positivos","")))))))
F49: =IF(OR($A49="",B49="",B49<=0,Séries!Q48=""),"",B49/Séries!Q48-1) | G49: =IF(OR($A49="",C49="",C49<=0,Séries!R48=""),"",C49/Séries!R48-1) | H49: =IF(OR($A49="",D49="",D49<=0,Séries!S48=""),"",D49/Séries!S48-1) | I49: =IF(OR($A49="",E49="",E49<=0,Séries!T48=""),"",E49/Séries!T48-1) | K49: =IF(COUNTA(A49:E49)=0,"",IF(A49="","Preencha a data",IF(NOT(ISNUMBER(A49)),"Data inválida",IF(OR(A49<36526,A49>73050,A49<>INT(A49)),"Data inválida",IF(A49<=Séries!U48,"Data repetida / fora de ordem",IF(COUNTA(B49:E49)<>COUNT(B49:E49),"Use preços numéricos",IF(OR(AND(ISNUMBER(B49),B49<=0),AND(ISNUMBER(C49),C49<=0),AND(ISNUMBER(D49),D49<=0),AND(ISNUMBER(E49),E49<=0)),"Use preços positivos","")))))))
... F1007: =IF(OR($A1007="",B1007="",B1007<=0,Séries!Q1006=""),"",B1007/Séries!Q1006-1) | G1007: =IF(OR($A1007="",C1007="",C1007<=0,Séries!R1006=""),"",C1007/Séries!R1006-1) | H1007: =IF(OR($A1007="",D1007="",D1007<=0,Séries!S1006=""),"",D1007/Séries!S1006-1) | I1007: =IF(OR($A1007="",E1007="",E1007<=0,Séries!T1006=""),"",E1007/Séries!T1006-1) | K1007: =IF(COUNTA(A1007:E1007)=0,"",IF(A1007="","Preencha a data",IF(NOT(ISNUMBER(A1007)),"Data inválida",IF(OR(A1007<36526,A1007>73050,A1007<>INT(A1007)),"Data inválida",IF(A1007<=Séries!U1006,"Data repetida / fora de ordem",IF(COUNTA(B1007:E1007)<>COUNT(B1007:E1007),"Use preços numéricos",IF(OR(AND(ISNUMBER(B1007),B1007<=0),AND(ISNUMBER(C1007),C1007<=0),AND(ISNUMBER(D1007),D1007<=0),AND(ISNUMBER(E1007),E1007<=0)),"Use preços positivos","")))))))

Sheet Fontes e guia
A1: Fontes de cotação e guia
A2: Links de pesquisa diária e origem das cotações preenchidas. Consulta inicial em 28/09/2026.
A4: Fonte | B4: Produto | C4: Praça / referência | D4: Unidade | E4: Modalidade | F4: Dados iniciais
A5: S1 | B5: Soja | C5: Paranaguá / PR | D5: R$/sc 60 kg | E5: À vista | F5: 17 a 25/09/2026
A6: Oficial | B6: https://cepea.org.br/br/indicador/soja.aspx
A7: Histórico | B7: https://www.noticiasagricolas.com.br/cotacoes/soja/soja-indicador-cepea-esalq-porto-paranagua
A9: S2 | B9: Milho | C9: Campinas / SP | D9: R$/sc 60 kg | E9: À vista | F9: 17 a 25/09/2026
A10: Oficial | B10: https://cepea.org.br/br/indicador/milho.aspx
A11: Histórico | B11: https://www.noticiasagricolas.com.br/cotacoes/milho/indicador-cepea-esalq-milho
A13: S3 | B13: Boi gordo | C13: São Paulo | D13: R$/@ 15 kg | E13: À vista | F13: 17 a 25/09/2026
A14: Oficial | B14: https://cepea.org.br/br/indicador/boi-gordo.aspx
A15: Histórico | B15: https://www.noticiasagricolas.com.br/cotacoes/boi-gordo/boi-gordo-indicador-esalq-bmf
A17: S4 | B17: Dólar PTAX | C17: BCB / venda | D17: R$/US$ | E17: PTAX venda | F17: 17 a 25/09/2026
A18: Oficial | B18: https://ptax.bcb.gov.br/ptax_internet/consultarUltimaCotacaoDolar.do
A19: Histórico | B19: https://www.noticiasagricolas.com.br/cotacoes/mercado-financeiro/cambio-ptax
A22: Outras consultas
A23: Notícias Agrícolas | C23: https://www.noticiasagricolas.com.br/cotacoes/
A24: Agrolink | C24: https://www.agrolink.com.br/cotacoes/
A25: PTAX por período | C25: https://ptax.bcb.gov.br/ptax_internet/consultaBoletim.do?method=consultarBoletim
A28: Como atualizar
A30: 1. Abra um dos links fixos no topo do Histórico e confirme a data, a praça, a unidade e a modalidade da cotação.
A31: 2. Na aba Histórico, use a próxima linha amarela. Digite a data e os preços nas colunas A:E. Use J para observações ou fonte.
A32: 3. Registre uma única linha por data, em ordem crescente. Para completar um produto, volte à linha da data correspondente.
A33: 4. Sem cotação no dia, deixe a célula vazia. O informativo compara cada produto com seu preço anterior disponível.
A34: 5. Veja o resumo e os gráficos na aba Informativo. Verde indica alta e vermelho indica queda; as variações também têm sinal.
A35: 6. Para usar sua própria praça, apague primeiro os preços iniciais e ajuste as referências. Mantenha a mesma série ao longo do tempo.
A36: 7. Não apague as fórmulas em F:I e K do Histórico nem nas demais abas. Há espaço para 1.000 datas (linhas 8 a 1007).
A37: 8. Os preços são preenchidos manualmente. Salve o arquivo após atualizar. Use Excel 2019 ou mais recente, com cálculo automático.
A40: Soja: indicador do porto de Paranaguá, saca de 60 kg. Milho: indicador de Campinas, saca de 60 kg, à vista e sem ICMS.
A41: Boi gordo: indicador de São Paulo, preço à vista por arroba de 15 kg, sem Funrural. Dólar: PTAX de venda, reais por US$ 1.
A42: S1–S3: indicadores CEPEA/ESALQ reproduzidos pelo Notícias Agrícolas. S4: Banco Central via Notícias Agrícolas; 25/09 confirmado no BCB.
A43: Os sete dias iniciais são cotações pesquisadas. As diferenças são calculadas com os preços disponíveis e podem variar por arredondamento.

Sheet Séries
A1: Séries dos gráficos
A2: Consulta automática das últimas 30 cotações de cada produto. Edite os preços somente na aba Histórico.
A3: Espaços no início indicam que ainda há menos de 30 observações. Produtos podem ter datas diferentes.
A5: Soja (R$/sc 60 kg) | E5: Milho (R$/sc 60 kg) | I5: Boi gordo (R$/@ 15 kg) | M5: Dólar PTAX (R$/US$)
A6: Data | B6: Preço | C6: Data no gráfico | E6: Data | F6: Preço | G6: Data no gráfico | I6: Data | J6: Preço | K6: Data no gráfico | M6: Data | N6: Preço | O6: Data no gráfico | Q6: Última soja válida | R6: Último milho válido | S6: Último boi válido | T6: Último dólar válido | U6: Última data válida
B7: =IF(A7="","",INDEX(Histórico!$B$8:$B$1007,MATCH(A7,Histórico!$A$8:$A$1007,0))) | C7: =IF(A7="","",TEXT(A7,"dd/mm")) | E7: =IF(OR(E8="",COUNTIFS(Histórico!$A$8:$A$1007,"<"&E8,Histórico!$A$8:$A$1007,">0",Histórico!$C$8:$C$1007,">0")=0),"",_xlfn.MAXIFS(Histórico!$A$8:$A$1007,Histórico!$A$8:$A$1007,"<"&E8,Histórico!$C$8:$C$1007,">0")) | F7: =IF(E7="","",INDEX(Histórico!$C$8:$C$1007,MATCH(E7,Histórico!$A$8:$A$1007,0))) | G7: =IF(E7="","",TEXT(E7,"dd/mm")) | I7: =IF(OR(I8="",COUNTIFS(Histórico!$A$8:$A$1007,"<"&I8,Histórico!$A$8:$A$1007,">0",Histórico!$D$8:$D$1007,">0")=0),"",_xlfn.MAXIFS(Histórico!$A$8:$A$1007,Histórico!$A$8:$A$1007,"<"&I8,Histórico!$D$8:$D$1007,">0")) | J7: =IF(I7="","",INDEX(Histórico!$D$8:$D$1007,MATCH(I7,Histórico!$A$8:$A$1007,0))) | K7: =IF(I7="","",TEXT(I7,"dd/mm")) | M7: =IF(OR(M8="",COUNTIFS(Histórico!$A$8:$A$1007,"<"&M8,Histórico!$A$8:$A$1007,">0",Histórico!$E$8:$E$1007,">0")=0),"",_xlfn.MAXIFS(Histórico!$A$8:$A$1007,Histórico!$A$8:$A$1007,"<"&M8,Histórico!$E$8:$E$1007,">0")) -> 46282 | N7: =IF(M7="","",INDEX(Histórico!$E$8:$E$1007,MATCH(M7,Histórico!$A$8:$A$1007,0))) -> 5.1521 | O7: =IF(M7="","",TEXT(M7,"dd/mm")) -> 17/09
A8: =IF(OR(A9="",COUNTIFS(Histórico!$A$8:$A$1007,"<"&A9,Histórico!$A$8:$A$1007,">0",Histórico!$B$8:$B$1007,">0")=0),"",_xlfn.MAXIFS(Histórico!$A$8:$A$1007,Histórico!$A$8:$A$1007,"<"&A9,Histórico!$B$8:$B$1007,">0")) -> 46282 | B8: =IF(A8="","",INDEX(Histórico!$B$8:$B$1007,MATCH(A8,Histórico!$A$8:$A$1007,0))) -> 162.02 | C8: =IF(A8="","",TEXT(A8,"dd/mm")) -> 17/09 | E8: =IF(OR(E9="",COUNTIFS(Histórico!$A$8:$A$1007,"<"&E9,Histórico!$A$8:$A$1007,">0",Histórico!$C$8:$C$1007,">0")=0),"",_xlfn.MAXIFS(Histórico!$A$8:$A$1007,Histórico!$A$8:$A$1007,"<"&E9,Histórico!$C$8:$C$1007,">0")) -> 46282 | F8: =IF(E8="","",INDEX(Histórico!$C$8:$C$1007,MATCH(E8,Histórico!$A$8:$A$1007,0))) -> 69.25 | G8: =IF(E8="","",TEXT(E8,"dd/mm")) -> 17/09 | I8: =IF(OR(I9="",COUNTIFS(Histórico!$A$8:$A$1007,"<"&I9,Histórico!$A$8:$A$1007,">0",Histórico!$D$8:$D$1007,">0")=0),"",_xlfn.MAXIFS(Histórico!$A$8:$A$1007,Histórico!$A$8:$A$1007,"<"&I9,Histórico!$D$8:$D$1007,">0")) -> 46282 | J8: =IF(I8="","",INDEX(Histórico!$D$8:$D$1007,MATCH(I8,Histórico!$A$8:$A$1007,0))) -> 352.55 | K8: =IF(I8="","",TEXT(I8,"dd/mm")) -> 17/09 | M8: =IF(OR(M9="",COUNTIFS(Histórico!$A$8:$A$1007,"<"&M9,Histórico!$A$8:$A$1007,">0",Histórico!$E$8:$E$1007,">0")=0),"",_xlfn.MAXIFS(Histórico!$A$8:$A$1007,Histórico!$A$8:$A$1007,"<"&M9,Histórico!$E$8:$E$1007,">0")) -> 46283 | N8: =IF(M8="","",INDEX(Histórico!$E$8:$E$1007,MATCH(M8,Histórico!$A$8:$A$1007,0))) -> 5.1575 | O8: =IF(M8="","",TEXT(M8,"dd/mm")) -> 18/09 | Q8: =IF(AND(ISNUMBER(Histórico!$A8),ISNUMBER(Histórico!B8),Histórico!B8>0),Histórico!B8,"") -> 162.02 | R8: =IF(AND(ISNUMBER(Histórico!$A8),ISNUMBER(Histórico!C8),Histórico!C8>0),Histórico!C8,"") -> 69.25 | S8: =IF(AND(ISNUMBER(Histórico!$A8),ISNUMBER(Histórico!D8),Histórico!D8>0),Histórico!D8,"") -> 352.55 | T8: =IF(AND(ISNUMBER(Histórico!$A8),ISNUMBER(Histórico!E8),Histórico!E8>0),Histórico!E8,"") -> 5.1521 | U8: =IF(ISNUMBER(Histórico!A8),Histórico!A8,0) -> 46282
A9: =IF(OR(A10="",COUNTIFS(Histórico!$A$8:$A$1007,"<"&A10,Histórico!$A$8:$A$1007,">0",Histórico!$B$8:$B$1007,">0")=0),"",_xlfn.MAXIFS(Histórico!$A$8:$A$1007,Histórico!$A$8:$A$1007,"<"&A10,Histórico!$B$8:$B$1007,">0")) -> 46283 | B9: =IF(A9="","",INDEX(Histórico!$B$8:$B$1007,MATCH(A9,Histórico!$A$8:$A$1007,0))) -> 161.89 | C9: =IF(A9="","",TEXT(A9,"dd/mm")) -> 18/09 | E9: =IF(OR(E10="",COUNTIFS(Histórico!$A$8:$A$1007,"<"&E10,Histórico!$A$8:$A$1007,">0",Histórico!$C$8:$C$1007,">0")=0),"",_xlfn.MAXIFS(Histórico!$A$8:$A$1007,Histórico!$A$8:$A$1007,"<"&E10,Histórico!$C$8:$C$1007,">0")) -> 46283 | F9: =IF(E9="","",INDEX(Histórico!$C$8:$C$1007,MATCH(E9,Histórico!$A$8:$A$1007,0))) -> 69.29 | G9: =IF(E9="","",TEXT(E9,"dd/mm")) -> 18/09 | I9: =IF(OR(I10="",COUNTIFS(Histórico!$A$8:$A$1007,"<"&I10,Histórico!$A$8:$A$1007,">0",Histórico!$D$8:$D$1007,">0")=0),"",_xlfn.MAXIFS(Histórico!$A$8:$A$1007,Histórico!$A$8:$A$1007,"<"&I10,Histórico!$D$8:$D$1007,">0")) -> 46283 | J9: =IF(I9="","",INDEX(Histórico!$D$8:$D$1007,MATCH(I9,Histórico!$A$8:$A$1007,0))) -> 352.9 | K9: =IF(I9="","",TEXT(I9,"dd/mm")) -> 18/09 | M9: =IF(OR(M10="",COUNTIFS(Histórico!$A$8:$A$1007,"<"&M10,Histórico!$A$8:$A$1007,">0",Histórico!$E$8:$E$1007,">0")=0),"",_xlfn.MAXIFS(Histórico!$A$8:$A$1007,Histórico!$A$8:$A$1007,"<"&M10,Histórico!$E$8:$E$1007,">0")) -> 46286 | N9: =IF(M9="","",INDEX(Histórico!$E$8:$E$1007,MATCH(M9,Histórico!$A$8:$A$1007,0))) -> 5.1117 | O9: =IF(M9="","",TEXT(M9,"dd/mm")) -> 21/09 | Q9: =IF(AND(ISNUMBER(Histórico!$A9),ISNUMBER(Histórico!B9),Histórico!B9>0),Histórico!B9,Q8) -> 161.89 | R9: =IF(AND(ISNUMBER(Histórico!$A9),ISNUMBER(Histórico!C9),Histórico!C9>0),Histórico!C9,R8) -> 69.29 | S9: =IF(AND(ISNUMBER(Histórico!$A9),ISNUMBER(Histórico!D9),Histórico!D9>0),Histórico!D9,S8) -> 352.9 | T9: =IF(AND(ISNUMBER(Histórico!$A9),ISNUMBER(Histórico!E9),Histórico!E9>0),Histórico!E9,T8) -> 5.1575 | U9: =IF(ISNUMBER(Histórico!A9),Histórico!A9,U8) -> 46283
A10: =IF(OR(A11="",COUNTIFS(Histórico!$A$8:$A$1007,"<"&A11,Histórico!$A$8:$A$1007,">0",Histórico!$B$8:$B$1007,">0")=0),"",_xlfn.MAXIFS(Histórico!$A$8:$A$1007,Histórico!$A$8:$A$1007,"<"&A11,Histórico!$B$8:$B$1007,">0")) -> 46286 | B10: =IF(A10="","",INDEX(Histórico!$B$8:$B$1007,MATCH(A10,Histórico!$A$8:$A$1007,0))) -> 161.52 | C10: =IF(A10="","",TEXT(A10,"dd/mm")) -> 21/09 | E10: =IF(OR(E11="",COUNTIFS(Histórico!$A$8:$A$1007,"<"&E11,Histórico!$A$8:$A$1007,">0",Histórico!$C$8:$C$1007,">0")=0),"",_xlfn.MAXIFS(Histórico!$A$8:$A$1007,Histórico!$A$8:$A$1007,"<"&E11,Histórico!$C$8:$C$1007,">0")) -> 46286 | F10: =IF(E10="","",INDEX(Histórico!$C$8:$C$1007,MATCH(E10,Histórico!$A$8:$A$1007,0))) -> 69.62 | G10: =IF(E10="","",TEXT(E10,"dd/mm")) -> 21/09 | I10: =IF(OR(I11="",COUNTIFS(Histórico!$A$8:$A$1007,"<"&I11,Histórico!$A$8:$A$1007,">0",Histórico!$D$8:$D$1007,">0")=0),"",_xlfn.MAXIFS(Histórico!$A$8:$A$1007,Histórico!$A$8:$A$1007,"<"&I11,Histórico!$D$8:$D$1007,">0")) -> 46286 | J10: =IF(I10="","",INDEX(Histórico!$D$8:$D$1007,MATCH(I10,Histórico!$A$8:$A$1007,0))) -> 354.65 | K10: =IF(I10="","",TEXT(I10,"dd/mm")) -> 21/09 | M10: =IF(OR(M11="",COUNTIFS(Histórico!$A$8:$A$1007,"<"&M11,Histórico!$A$8:$A$1007,">0",Histórico!$E$8:$E$1007,">0")=0),"",_xlfn.MAXIFS(Histórico!$A$8:$A$1007,Histórico!$A$8:$A$1007,"<"&M11,Histórico!$E$8:$E$1007,">0")) -> 46287 | N10: =IF(M10="","",INDEX(Histórico!$E$8:$E$1007,MATCH(M10,Histórico!$A$8:$A$1007,0))) -> 5.1161 | O10: =IF(M10="","",TEXT(M10,"dd/mm")) -> 22/09 | Q10: =IF(AND(ISNUMBER(Histórico!$A10),ISNUMBER(Histórico!B10),Histórico!B10>0),Histórico!B10,Q9) -> 161.52 | R10: =IF(AND(ISNUMBER(Histórico!$A10),ISNUMBER(Histórico!C10),Histórico!C10>0),Histórico!C10,R9) -> 69.62 | S10: =IF(AND(ISNUMBER(Histórico!$A10),ISNUMBER(Histórico!D10),Histórico!D10>0),Histórico!D10,S9) -> 354.65 | T10: =IF(AND(ISNUMBER(Histórico!$A10),ISNUMBER(Histórico!E10),Histórico!E10>0),Histórico!E10,T9) -> 5.1117 | U10: =IF(ISNUMBER(Histórico!A10),Histórico!A10,U9) -> 46286
A11: =IF(OR(A12="",COUNTIFS(Histórico!$A$8:$A$1007,"<"&A12,Histórico!$A$8:$A$1007,">0",Histórico!$B$8:$B$1007,">0")=0),"",_xlfn.MAXIFS(Histórico!$A$8:$A$1007,Histórico!$A$8:$A$1007,"<"&A12,Histórico!$B$8:$B$1007,">0")) -> 46287 | B11: =IF(A11="","",INDEX(Histórico!$B$8:$B$1007,MATCH(A11,Histórico!$A$8:$A$1007,0))) -> 161.93 | C11: =IF(A11="","",TEXT(A11,"dd/mm")) -> 22/09 | E11: =IF(OR(E12="",COUNTIFS(Histórico!$A$8:$A$1007,"<"&E12,Histórico!$A$8:$A$1007,">0",Histórico!$C$8:$C$1007,">0")=0),"",_xlfn.MAXIFS(Histórico!$A$8:$A$1007,Histórico!$A$8:$A$1007,"<"&E12,Histórico!$C$8:$C$1007,">0")) -> 46287 | F11: =IF(E11="","",INDEX(Histórico!$C$8:$C$1007,MATCH(E11,Histórico!$A$8:$A$1007,0))) -> 69.74 | G11: =IF(E11="","",TEXT(E11,"dd/mm")) -> 22/09 | I11: =IF(OR(I12="",COUNTIFS(Histórico!$A$8:$A$1007,"<"&I12,Histórico!$A$8:$A$1007,">0",Histórico!$D$8:$D$1007,">0")=0),"",_xlfn.MAXIFS(Histórico!$A$8:$A$1007,Histórico!$A$8:$A$1007,"<"&I12,Histórico!$D$8:$D$1007,">0")) -> 46287 | J11: =IF(I11="","",INDEX(Histórico!$D$8:$D$1007,MATCH(I11,Histórico!$A$8:$A$1007,0))) -> 356.1 | K11: =IF(I11="","",TEXT(I11,"dd/mm")) -> 22/09 | M11: =IF(OR(M12="",COUNTIFS(Histórico!$A$8:$A$1007,"<"&M12,Histórico!$A$8:$A$1007,">0",Histórico!$E$8:$E$1007,">0")=0),"",_xlfn.MAXIFS(Histórico!$A$8:$A$1007,Histórico!$A$8:$A$1007,"<"&M12,Histórico!$E$8:$E$1007,">0")) -> 46288 | N11: =IF(M11="","",INDEX(Histórico!$E$8:$E$1007,MATCH(M11,Histórico!$A$8:$A$1007,0))) -> 5.1414 | O11: =IF(M11="","",TEXT(M11,"dd/mm")) -> 23/09 | Q11: =IF(AND(ISNUMBER(Histórico!$A11),ISNUMBER(Histórico!B11),Histórico!B11>0),Histórico!B11,Q10) -> 161.93 | R11: =IF(AND(ISNUMBER(Histórico!$A11),ISNUMBER(Histórico!C11),Histórico!C11>0),Histórico!C11,R10) -> 69.74 | S11: =IF(AND(ISNUMBER(Histórico!$A11),ISNUMBER(Histórico!D11),Histórico!D11>0),Histórico!D11,S10) -> 356.1 | T11: =IF(AND(ISNUMBER(Histórico!$A11),ISNUMBER(Histórico!E11),Histórico!E11>0),Histórico!E11,T10) -> 5.1161 | U11: =IF(ISNUMBER(Histórico!A11),Histórico!A11,U10) -> 46287
A12: =IF(OR(A13="",COUNTIFS(Histórico!$A$8:$A$1007,"<"&A13,Histórico!$A$8:$A$1007,">0",Histórico!$B$8:$B$1007,">0")=0),"",_xlfn.MAXIFS(Histórico!$A$8:$A$1007,Histórico!$A$8:$A$1007,"<"&A13,Histórico!$B$8:$B$1007,">0")) -> 46288 | B12: =IF(A12="","",INDEX(Histórico!$B$8:$B$1007,MATCH(A12,Histórico!$A$8:$A$1007,0))) -> 161.65 | C12: =IF(A12="","",TEXT(A12,"dd/mm")) -> 23/09 | E12: =IF(OR(E13="",COUNTIFS(Histórico!$A$8:$A$1007,"<"&E13,Histórico!$A$8:$A$1007,">0",Histórico!$C$8:$C$1007,">0")=0),"",_xlfn.MAXIFS(Histórico!$A$8:$A$1007,Histórico!$A$8:$A$1007,"<"&E13,Histórico!$C$8:$C$1007,">0")) -> 46288 | F12: =IF(E12="","",INDEX(Histórico!$C$8:$C$1007,MATCH(E12,Histórico!$A$8:$A$1007,0))) -> 69.82 | G12: =IF(E12="","",TEXT(E12,"dd/mm")) -> 23/09 | I12: =IF(OR(I13="",COUNTIFS(Histórico!$A$8:$A$1007,"<"&I13,Histórico!$A$8:$A$1007,">0",Histórico!$D$8:$D$1007,">0")=0),"",_xlfn.MAXIFS(Histórico!$A$8:$A$1007,Histórico!$A$8:$A$1007,"<"&I13,Histórico!$D$8:$D$1007,">0")) -> 46288 | J12: =IF(I12="","",INDEX(Histórico!$D$8:$D$1007,MATCH(I12,Histórico!$A$8:$A$1007,0))) -> 357.4 | K12: =IF(I12="","",TEXT(I12,"dd/mm")) -> 23/09 | M12: =IF(OR(M13="",COUNTIFS(Histórico!$A$8:$A$1007,"<"&M13,Histórico!$A$8:$A$1007,">0",Histórico!$E$8:$E$1007,">0")=0),"",_xlfn.MAXIFS(Histórico!$A$8:$A$1007,Histórico!$A$8:$A$1007,"<"&M13,Histórico!$E$8:$E$1007,">0")) -> 46289 | N12: =IF(M12="","",INDEX(Histórico!$E$8:$E$1007,MATCH(M12,Histórico!$A$8:$A$1007,0))) -> 5.1795 | O12: =IF(M12="","",TEXT(M12,"dd/mm")) -> 24/09 | Q12: =IF(AND(ISNUMBER(Histórico!$A12),ISNUMBER(Histórico!B12),Histórico!B12>0),Histórico!B12,Q11) -> 161.65 | R12: =IF(AND(ISNUMBER(Histórico!$A12),ISNUMBER(Histórico!C12),Histórico!C12>0),Histórico!C12,R11) -> 69.82 | S12: =IF(AND(ISNUMBER(Histórico!$A12),ISNUMBER(Histórico!D12),Histórico!D12>0),Histórico!D12,S11) -> 357.4 | T12: =IF(AND(ISNUMBER(Histórico!$A12),ISNUMBER(Histórico!E12),Histórico!E12>0),Histórico!E12,T11) -> 5.1414 | U12: =IF(ISNUMBER(Histórico!A12),Histórico!A12,U11) -> 46288
A13: =IF(OR(A14="",COUNTIFS(Histórico!$A$8:$A$1007,"<"&A14,Histórico!$A$8:$A$1007,">0",Histórico!$B$8:$B$1007,">0")=0),"",_xlfn.MAXIFS(Histórico!$A$8:$A$1007,Histórico!$A$8:$A$1007,"<"&A14,Histórico!$B$8:$B$1007,">0")) -> 46289 | B13: =IF(A13="","",INDEX(Histórico!$B$8:$B$1007,MATCH(A13,Histórico!$A$8:$A$1007,0))) -> 161.84 | C13: =IF(A13="","",TEXT(A13,"dd/mm")) -> 24/09 | E13: =IF(OR(E14="",COUNTIFS(Histórico!$A$8:$A$1007,"<"&E14,Histórico!$A$8:$A$1007,">0",Histórico!$C$8:$C$1007,">0")=0),"",_xlfn.MAXIFS(Histórico!$A$8:$A$1007,Histórico!$A$8:$A$1007,"<"&E14,Histórico!$C$8:$C$1007,">0")) -> 46289 | F13: =IF(E13="","",INDEX(Histórico!$C$8:$C$1007,MATCH(E13,Histórico!$A$8:$A$1007,0))) -> 69.81 | G13: =IF(E13="","",TEXT(E13,"dd/mm")) -> 24/09 | I13: =IF(OR(I14="",COUNTIFS(Histórico!$A$8:$A$1007,"<"&I14,Histórico!$A$8:$A$1007,">0",Histórico!$D$8:$D$1007,">0")=0),"",_xlfn.MAXIFS(Histórico!$A$8:$A$1007,Histórico!$A$8:$A$1007,"<"&I14,Histórico!$D$8:$D$1007,">0")) -> 46289 | J13: =IF(I13="","",INDEX(Histórico!$D$8:$D$1007,MATCH(I13,Histórico!$A$8:$A$1007,0))) -> 358.2 | K13: =IF(I13="","",TEXT(I13,"dd/mm")) -> 24/09 | M13: =IF(OR(M14="",COUNTIFS(Histórico!$A$8:$A$1007,"<"&M14,Histórico!$A$8:$A$1007,">0",Histórico!$E$8:$E$1007,">0")=0),"",_xlfn.MAXIFS(Histórico!$A$8:$A$1007,Histórico!$A$8:$A$1007,"<"&M14,Histórico!$E$8:$E$1007,">0")) -> 46290 | N13: =IF(M13="","",INDEX(Histórico!$E$8:$E$1007,MATCH(M13,Histórico!$A$8:$A$1007,0))) -> 5.1991 | O13: =IF(M13="","",TEXT(M13,"dd/mm")) -> 25/09 | Q13: =IF(AND(ISNUMBER(Histórico!$A13),ISNUMBER(Histórico!B13),Histórico!B13>0),Histórico!B13,Q12) -> 161.84 | R13: =IF(AND(ISNUMBER(Histórico!$A13),ISNUMBER(Histórico!C13),Histórico!C13>0),Histórico!C13,R12) -> 69.81 | S13: =IF(AND(ISNUMBER(Histórico!$A13),ISNUMBER(Histórico!D13),Histórico!D13>0),Histórico!D13,S12) -> 358.2 | T13: =IF(AND(ISNUMBER(Histórico!$A13),ISNUMBER(Histórico!E13),Histórico!E13>0),Histórico!E13,T12) -> 5.1795 | U13: =IF(ISNUMBER(Histórico!A13),Histórico!A13,U12) -> 46289
A14: =IF(OR(A15="",COUNTIFS(Histórico!$A$8:$A$1007,"<"&A15,Histórico!$A$8:$A$1007,">0",Histórico!$B$8:$B$1007,">0")=0),"",_xlfn.MAXIFS(Histórico!$A$8:$A$1007,Histórico!$A$8:$A$1007,"<"&A15,Histórico!$B$8:$B$1007,">0")) -> 46290 | B14: =IF(A14="","",INDEX(Histórico!$B$8:$B$1007,MATCH(A14,Histórico!$A$8:$A$1007,0))) -> 161 | C14: =IF(A14="","",TEXT(A14,"dd/mm")) -> 25/09 | E14: =IF(OR(E15="",COUNTIFS(Histórico!$A$8:$A$1007,"<"&E15,Histórico!$A$8:$A$1007,">0",Histórico!$C$8:$C$1007,">0")=0),"",_xlfn.MAXIFS(Histórico!$A$8:$A$1007,Histórico!$A$8:$A$1007,"<"&E15,Histórico!$C$8:$C$1007,">0")) -> 46290 | F14: =IF(E14="","",INDEX(Histórico!$C$8:$C$1007,MATCH(E14,Histórico!$A$8:$A$1007,0))) -> 69.65 | G14: =IF(E14="","",TEXT(E14,"dd/mm")) -> 25/09 | I14: =IF(OR(I15="",COUNTIFS(Histórico!$A$8:$A$1007,"<"&I15,Histórico!$A$8:$A$1007,">0",Histórico!$D$8:$D$1007,">0")=0),"",_xlfn.MAXIFS(Histórico!$A$8:$A$1007,Histórico!$A$8:$A$1007,"<"&I15,Histórico!$D$8:$D$1007,">0")) -> 46290 | J14: =IF(I14="","",INDEX(Histórico!$D$8:$D$1007,MATCH(I14,Histórico!$A$8:$A$1007,0))) -> 358.8 | K14: =IF(I14="","",TEXT(I14,"dd/mm")) -> 25/09 | M14: =IF(OR(M15="",COUNTIFS(Histórico!$A$8:$A$1007,"<"&M15,Histórico!$A$8:$A$1007,">0",Histórico!$E$8:$E$1007,">0")=0),"",_xlfn.MAXIFS(Histórico!$A$8:$A$1007,Histórico!$A$8:$A$1007,"<"&M15,Histórico!$E$8:$E$1007,">0")) -> 46293 | N14: =IF(M14="","",INDEX(Histórico!$E$8:$E$1007,MATCH(M14,Histórico!$A$8:$A$1007,0))) -> 5.2132 | O14: =IF(M14="","",TEXT(M14,"dd/mm")) -> 28/09 | Q14: =IF(AND(ISNUMBER(Histórico!$A14),ISNUMBER(Histórico!B14),Histórico!B14>0),Histórico!B14,Q13) -> 161 | R14: =IF(AND(ISNUMBER(Histórico!$A14),ISNUMBER(Histórico!C14),Histórico!C14>0),Histórico!C14,R13) -> 69.65 | S14: =IF(AND(ISNUMBER(Histórico!$A14),ISNUMBER(Histórico!D14),Histórico!D14>0),Histórico!D14,S13) -> 358.8 | T14: =IF(AND(ISNUMBER(Histórico!$A14),ISNUMBER(Histórico!E14),Histórico!E14>0),Histórico!E14,T13) -> 5.1991 | U14: =IF(ISNUMBER(Histórico!A14),Histórico!A14,U13) -> 46290
A15: =IF(OR(A16="",COUNTIFS(Histórico!$A$8:$A$1007,"<"&A16,Histórico!$A$8:$A$1007,">0",Histórico!$B$8:$B$1007,">0")=0),"",_xlfn.MAXIFS(Histórico!$A$8:$A$1007,Histórico!$A$8:$A$1007,"<"&A16,Histórico!$B$8:$B$1007,">0")) -> 46293 | B15: =IF(A15="","",INDEX(Histórico!$B$8:$B$1007,MATCH(A15,Histórico!$A$8:$A$1007,0))) -> 160.43 | C15: =IF(A15="","",TEXT(A15,"dd/mm")) -> 28/09 | E15: =IF(OR(E16="",COUNTIFS(Histórico!$A$8:$A$1007,"<"&E16,Histórico!$A$8:$A$1007,">0",Histórico!$C$8:$C$1007,">0")=0),"",_xlfn.MAXIFS(Histórico!$A$8:$A$1007,Histórico!$A$8:$A$1007,"<"&E16,Histórico!$C$8:$C$1007,">0")) -> 46293 | F15: =IF(E15="","",INDEX(Histórico!$C$8:$C$1007,MATCH(E15,Histórico!$A$8:$A$1007,0))) -> 69.48 | G15: =IF(E15="","",TEXT(E15,"dd/mm")) -> 28/09 | I15: =IF(OR(I16="",COUNTIFS(Histórico!$A$8:$A$1007,"<"&I16,Histórico!$A$8:$A$1007,">0",Histórico!$D$8:$D$1007,">0")=0),"",_xlfn.MAXIFS(Histórico!$A$8:$A$1007,Histórico!$A$8:$A$1007,"<"&I16,Histórico!$D$8:$D$1007,">0")) -> 46293 | J15: =IF(I15="","",INDEX(Histórico!$D$8:$D$1007,MATCH(I15,Histórico!$A$8:$A$1007,0))) -> 359.95 | K15: =IF(I15="","",TEXT(I15,"dd/mm")) -> 28/09 | M15: =IF(OR(M16="",COUNTIFS(Histórico!$A$8:$A$1007,"<"&M16,Histórico!$A$8:$A$1007,">0",Histórico!$E$8:$E$1007,">0")=0),"",_xlfn.MAXIFS(Histórico!$A$8:$A$1007,Histórico!$A$8:$A$1007,"<"&M16,Histórico!$E$8:$E$1007,">0")) -> 46294 | N15: =IF(M15="","",INDEX(Histórico!$E$8:$E$1007,MATCH(M15,Histórico!$A$8:$A$1007,0))) -> 5.2204 | O15: =IF(M15="","",TEXT(M15,"dd/mm")) -> 29/09 | Q15: =IF(AND(ISNUMBER(Histórico!$A15),ISNUMBER(Histórico!B15),Histórico!B15>0),Histórico!B15,Q14) -> 160.43 | R15: =IF(AND(ISNUMBER(Histórico!$A15),ISNUMBER(Histórico!C15),Histórico!C15>0),Histórico!C15,R14) -> 69.48 | S15: =IF(AND(ISNUMBER(Histórico!$A15),ISNUMBER(Histórico!D15),Histórico!D15>0),Histórico!D15,S14) -> 359.95 | T15: =IF(AND(ISNUMBER(Histórico!$A15),ISNUMBER(Histórico!E15),Histórico!E15>0),Histórico!E15,T14) -> 5.2132 | U15: =IF(ISNUMBER(Histórico!A15),Histórico!A15,U14) -> 46293
A16: =IF(OR(A17="",COUNTIFS(Histórico!$A$8:$A$1007,"<"&A17,Histórico!$A$8:$A$1007,">0",Histórico!$B$8:$B$1007,">0")=0),"",_xlfn.MAXIFS(Histórico!$A$8:$A$1007,Histórico!$A$8:$A$1007,"<"&A17,Histórico!$B$8:$B$1007,">0")) -> 46294 | B16: =IF(A16="","",INDEX(Histórico!$B$8:$B$1007,MATCH(A16,Histórico!$A$8:$A$1007,0))) -> 161.27 | C16: =IF(A16="","",TEXT(A16,"dd/mm")) -> 29/09 | E16: =IF(OR(E17="",COUNTIFS(Histórico!$A$8:$A$1007,"<"&E17,Histórico!$A$8:$A$1007,">0",Histórico!$C$8:$C$1007,">0")=0),"",_xlfn.MAXIFS(Histórico!$A$8:$A$1007,Histórico!$A$8:$A$1007,"<"&E17,Histórico!$C$8:$C$1007,">0")) -> 46294 | F16: =IF(E16="","",INDEX(Histórico!$C$8:$C$1007,MATCH(E16,Histórico!$A$8:$A$1007,0))) -> 69.2 | G16: =IF(E16="","",TEXT(E16,"dd/mm")) -> 29/09 | I16: =IF(OR(I17="",COUNTIFS(Histórico!$A$8:$A$1007,"<"&I17,Histórico!$A$8:$A$1007,">0",Histórico!$D$8:$D$1007,">0")=0),"",_xlfn.MAXIFS(Histórico!$A$8:$A$1007,Histórico!$A$8:$A$1007,"<"&I17,Histórico!$D$8:$D$1007,">0")) -> 46294 | J16: =IF(I16="","",INDEX(Histórico!$D$8:$D$1007,MATCH(I16,Histórico!$A$8:$A$1007,0))) -> 363.05 | K16: =IF(I16="","",TEXT(I16,"dd/mm")) -> 29/09 | M16: =IF(OR(M17="",COUNTIFS(Histórico!$A$8:$A$1007,"<"&M17,Histórico!$A$8:$A$1007,">0",Histórico!$E$8:$E$1007,">0")=0),"",_xlfn.MAXIFS(Histórico!$A$8:$A$1007,Histórico!$A$8:$A$1007,"<"&M17,Histórico!$E$8:$E$1007,">0")) -> 46295 | N16: =IF(M16="","",INDEX(Histórico!$E$8:$E$1007,MATCH(M16,Histórico!$A$8:$A$1007,0))) -> 5.1809 | O16: =IF(M16="","",TEXT(M16,"dd/mm")) -> 30/09 | Q16: =IF(AND(ISNUMBER(Histórico!$A16),ISNUMBER(Histórico!B16),Histórico!B16>0),Histórico!B16,Q15) -> 161.27 | R16: =IF(AND(ISNUMBER(Histórico!$A16),ISNUMBER(Histórico!C16),Histórico!C16>0),Histórico!C16,R15) -> 69.2 | S16: =IF(AND(ISNUMBER(Histórico!$A16),ISNUMBER(Histórico!D16),Histórico!D16>0),Histórico!D16,S15) -> 363.05 | T16: =IF(AND(ISNUMBER(Histórico!$A16),ISNUMBER(Histórico!E16),Histórico!E16>0),Histórico!E16,T15) -> 5.2204 | U16: =IF(ISNUMBER(Histórico!A16),Histórico!A16,U15) -> 46294
A17: =IF(OR(A18="",COUNTIFS(Histórico!$A$8:$A$1007,"<"&A18,Histórico!$A$8:$A$1007,">0",Histórico!$B$8:$B$1007,">0")=0),"",_xlfn.MAXIFS(Histórico!$A$8:$A$1007,Histórico!$A$8:$A$1007,"<"&A18,Histórico!$B$8:$B$1007,">0")) -> 46295 | B17: =IF(A17="","",INDEX(Histórico!$B$8:$B$1007,MATCH(A17,Histórico!$A$8:$A$1007,0))) -> 161.56 | C17: =IF(A17="","",TEXT(A17,"dd/mm")) -> 30/09 | E17: =IF(OR(E18="",COUNTIFS(Histórico!$A$8:$A$1007,"<"&E18,Histórico!$A$8:$A$1007,">0",Histórico!$C$8:$C$1007,">0")=0),"",_xlfn.MAXIFS(Histórico!$A$8:$A$1007,Histórico!$A$8:$A$1007,"<"&E18,Histórico!$C$8:$C$1007,">0")) -> 46295 | F17: =IF(E17="","",INDEX(Histórico!$C$8:$C$1007,MATCH(E17,Histórico!$A$8:$A$1007,0))) -> 68.67 | G17: =IF(E17="","",TEXT(E17,"dd/mm")) -> 30/09 | I17: =IF(OR(I18="",COUNTIFS(Histórico!$A$8:$A$1007,"<"&I18,Histórico!$A$8:$A$1007,">0",Histórico!$D$8:$D$1007,">0")=0),"",_xlfn.MAXIFS(Histórico!$A$8:$A$1007,Histórico!$A$8:$A$1007,"<"&I18,Histórico!$D$8:$D$1007,">0")) -> 46295 | J17: =IF(I17="","",INDEX(Histórico!$D$8:$D$1007,MATCH(I17,Histórico!$A$8:$A$1007,0))) -> 364.3 | K17: =IF(I17="","",TEXT(I17,"dd/mm")) -> 30/09 | M17: =IF(OR(M18="",COUNTIFS(Histórico!$A$8:$A$1007,"<"&M18,Histórico!$A$8:$A$1007,">0",Histórico!$E$8:$E$1007,">0")=0),"",_xlfn.MAXIFS(Histórico!$A$8:$A$1007,Histórico!$A$8:$A$1007,"<"&M18,Histórico!$E$8:$E$1007,">0")) -> 46296 | N17: =IF(M17="","",INDEX(Histórico!$E$8:$E$1007,MATCH(M17,Histórico!$A$8:$A$1007,0))) -> 5.2079 | O17: =IF(M17="","",TEXT(M17,"dd/mm")) -> 01/10 | Q17: =IF(AND(ISNUMBER(Histórico!$A17),ISNUMBER(Histórico!B17),Histórico!B17>0),Histórico!B17,Q16) -> 161.56 | R17: =IF(AND(ISNUMBER(Histórico!$A17),ISNUMBER(Histórico!C17),Histórico!C17>0),Histórico!C17,R16) -> 68.67 | S17: =IF(AND(ISNUMBER(Histórico!$A17),ISNUMBER(Histórico!D17),Histórico!D17>0),Histórico!D17,S16) -> 364.3 | T17: =IF(AND(ISNUMBER(Histórico!$A17),ISNUMBER(Histórico!E17),Histórico!E17>0),Histórico!E17,T16) -> 5.1809 | U17: =IF(ISNUMBER(Histórico!A17),Histórico!A17,U16) -> 46295
A18: =IF(OR(A19="",COUNTIFS(Histórico!$A$8:$A$1007,"<"&A19,Histórico!$A$8:$A$1007,">0",Histórico!$B$8:$B$1007,">0")=0),"",_xlfn.MAXIFS(Histórico!$A$8:$A$1007,Histórico!$A$8:$A$1007,"<"&A19,Histórico!$B$8:$B$1007,">0")) -> 46296 | B18: =IF(A18="","",INDEX(Histórico!$B$8:$B$1007,MATCH(A18,Histórico!$A$8:$A$1007,0))) -> 160.9 | C18: =IF(A18="","",TEXT(A18,"dd/mm")) -> 01/10 | E18: =IF(OR(E19="",COUNTIFS(Histórico!$A$8:$A$1007,"<"&E19,Histórico!$A$8:$A$1007,">0",Histórico!$C$8:$C$1007,">0")=0),"",_xlfn.MAXIFS(Histórico!$A$8:$A$1007,Histórico!$A$8:$A$1007,"<"&E19,Histórico!$C$8:$C$1007,">0")) -> 46296 | F18: =IF(E18="","",INDEX(Histórico!$C$8:$C$1007,MATCH(E18,Histórico!$A$8:$A$1007,0))) -> 68.58 | G18: =IF(E18="","",TEXT(E18,"dd/mm")) -> 01/10 | I18: =IF(OR(I19="",COUNTIFS(Histórico!$A$8:$A$1007,"<"&I19,Histórico!$A$8:$A$1007,">0",Histórico!$D$8:$D$1007,">0")=0),"",_xlfn.MAXIFS(Histórico!$A$8:$A$1007,Histórico!$A$8:$A$1007,"<"&I19,Histórico!$D$8:$D$1007,">0")) -> 46296 | J18: =IF(I18="","",INDEX(Histórico!$D$8:$D$1007,MATCH(I18,Histórico!$A$8:$A$1007,0))) -> 366.5 | K18: =IF(I18="","",TEXT(I18,"dd/mm")) -> 01/10 | M18: =IF(OR(M19="",COUNTIFS(Histórico!$A$8:$A$1007,"<"&M19,Histórico!$A$8:$A$1007,">0",Histórico!$E$8:$E$1007,">0")=0),"",_xlfn.MAXIFS(Histórico!$A$8:$A$1007,Histórico!$A$8:$A$1007,"<"&M19,Histórico!$E$8:$E$1007,">0")) -> 46297 | N18: =IF(M18="","",INDEX(Histórico!$E$8:$E$1007,MATCH(M18,Histórico!$A$8:$A$1007,0))) -> 5.2238 | O18: =IF(M18="","",TEXT(M18,"dd/mm")) -> 02/10 | Q18: =IF(AND(ISNUMBER(Histórico!$A18),ISNUMBER(Histórico!B18),Histórico!B18>0),Histórico!B18,Q17) -> 160.9 | R18: =IF(AND(ISNUMBER(Histórico!$A18),ISNUMBER(Histórico!C18),Histórico!C18>0),Histórico!C18,R17) -> 68.58 | S18: =IF(AND(ISNUMBER(Histórico!$A18),ISNUMBER(Histórico!D18),Histórico!D18>0),Histórico!D18,S17) -> 366.5 | T18: =IF(AND(ISNUMBER(Histórico!$A18),ISNUMBER(Histórico!E18),Histórico!E18>0),Histórico!E18,T17) -> 5.2079 | U18: =IF(ISNUMBER(Histórico!A18),Histórico!A18,U17) -> 46296
A19: =IF(OR(A20="",COUNTIFS(Histórico!$A$8:$A$1007,"<"&A20,Histórico!$A$8:$A$1007,">0",Histórico!$B$8:$B$1007,">0")=0),"",_xlfn.MAXIFS(Histórico!$A$8:$A$1007,Histórico!$A$8:$A$1007,"<"&A20,Histórico!$B$8:$B$1007,">0")) -> 46297 | B19: =IF(A19="","",INDEX(Histórico!$B$8:$B$1007,MATCH(A19,Histórico!$A$8:$A$1007,0))) -> 159.94 | C19: =IF(A19="","",TEXT(A19,"dd/mm")) -> 02/10 | E19: =IF(OR(E20="",COUNTIFS(Histórico!$A$8:$A$1007,"<"&E20,Histórico!$A$8:$A$1007,">0",Histórico!$C$8:$C$1007,">0")=0),"",_xlfn.MAXIFS(Histórico!$A$8:$A$1007,Histórico!$A$8:$A$1007,"<"&E20,Histórico!$C$8:$C$1007,">0")) -> 46297 | F19: =IF(E19="","",INDEX(Histórico!$C$8:$C$1007,MATCH(E19,Histórico!$A$8:$A$1007,0))) -> 68.53 | G19: =IF(E19="","",TEXT(E19,"dd/mm")) -> 02/10 | I19: =IF(OR(I20="",COUNTIFS(Histórico!$A$8:$A$1007,"<"&I20,Histórico!$A$8:$A$1007,">0",Histórico!$D$8:$D$1007,">0")=0),"",_xlfn.MAXIFS(Histórico!$A$8:$A$1007,Histórico!$A$8:$A$1007,"<"&I20,Histórico!$D$8:$D$1007,">0")) -> 46297 | J19: =IF(I19="","",INDEX(Histórico!$D$8:$D$1007,MATCH(I19,Histórico!$A$8:$A$1007,0))) -> 369.9 | K19: =IF(I19="","",TEXT(I19,"dd/mm")) -> 02/10 | M19: =IF(OR(M20="",COUNTIFS(Histórico!$A$8:$A$1007,"<"&M20,Histórico!$A$8:$A$1007,">0",Histórico!$E$8:$E$1007,">0")=0),"",_xlfn.MAXIFS(Histórico!$A$8:$A$1007,Histórico!$A$8:$A$1007,"<"&M20,Histórico!$E$8:$E$1007,">0")) -> 46300 | N19: =IF(M19="","",INDEX(Histórico!$E$8:$E$1007,MATCH(M19,Histórico!$A$8:$A$1007,0))) -> 4.9859 | O19: =IF(M19="","",TEXT(M19,"dd/mm")) -> 05/10 | Q19: =IF(AND(ISNUMBER(Histórico!$A19),ISNUMBER(Histórico!B19),Histórico!B19>0),Histórico!B19,Q18) -> 159.94 | R19: =IF(AND(ISNUMBER(Histórico!$A19),ISNUMBER(Histórico!C19),Histórico!C19>0),Histórico!C19,R18) -> 68.53 | S19: =IF(AND(ISNUMBER(Histórico!$A19),ISNUMBER(Histórico!D19),Histórico!D19>0),Histórico!D19,S18) -> 369.9 | T19: =IF(AND(ISNUMBER(Histórico!$A19),ISNUMBER(Histórico!E19),Histórico!E19>0),Histórico!E19,T18) -> 5.2238 | U19: =IF(ISNUMBER(Histórico!A19),Histórico!A19,U18) -> 46297
A20: =IF(OR(A21="",COUNTIFS(Histórico!$A$8:$A$1007,"<"&A21,Histórico!$A$8:$A$1007,">0",Histórico!$B$8:$B$1007,">0")=0),"",_xlfn.MAXIFS(Histórico!$A$8:$A$1007,Histórico!$A$8:$A$1007,"<"&A21,Histórico!$B$8:$B$1007,">0")) -> 46300 | B20: =IF(A20="","",INDEX(Histórico!$B$8:$B$1007,MATCH(A20,Histórico!$A$8:$A$1007,0))) -> 158.09 | C20: =IF(A20="","",TEXT(A20,"dd/mm")) -> 05/10 | E20: =IF(OR(E21="",COUNTIFS(Histórico!$A$8:$A$1007,"<"&E21,Histórico!$A$8:$A$1007,">0",Histórico!$C$8:$C$1007,">0")=0),"",_xlfn.MAXIFS(Histórico!$A$8:$A$1007,Histórico!$A$8:$A$1007,"<"&E21,Histórico!$C$8:$C$1007,">0")) -> 46300 | F20: =IF(E20="","",INDEX(Histórico!$C$8:$C$1007,MATCH(E20,Histórico!$A$8:$A$1007,0))) -> 67.26 | G20: =IF(E20="","",TEXT(E20,"dd/mm")) -> 05/10 | I20: =IF(OR(I21="",COUNTIFS(Histórico!$A$8:$A$1007,"<"&I21,Histórico!$A$8:$A$1007,">0",Histórico!$D$8:$D$1007,">0")=0),"",_xlfn.MAXIFS(Histórico!$A$8:$A$1007,Histórico!$A$8:$A$1007,"<"&I21,Histórico!$D$8:$D$1007,">0")) -> 46300 | J20: =IF(I20="","",INDEX(Histórico!$D$8:$D$1007,MATCH(I20,Histórico!$A$8:$A$1007,0))) -> 372.95 | K20: =IF(I20="","",TEXT(I20,"dd/mm")) -> 05/10 | M20: =IF(OR(M21="",COUNTIFS(Histórico!$A$8:$A$1007,"<"&M21,Histórico!$A$8:$A$1007,">0",Histórico!$E$8:$E$1007,">0")=0),"",_xlfn.MAXIFS(Histórico!$A$8:$A$1007,Histórico!$A$8:$A$1007,"<"&M21,Histórico!$E$8:$E$1007,">0")) -> 46301 | N20: =IF(M20="","",INDEX(Histórico!$E$8:$E$1007,MATCH(M20,Histórico!$A$8:$A$1007,0))) -> 4.9698 | O20: =IF(M20="","",TEXT(M20,"dd/mm")) -> 06/10 | Q20: =IF(AND(ISNUMBER(Histórico!$A20),ISNUMBER(Histórico!B20),Histórico!B20>0),Histórico!B20,Q19) -> 158.09 | R20: =IF(AND(ISNUMBER(Histórico!$A20),ISNUMBER(Histórico!C20),Histórico!C20>0),Histórico!C20,R19) -> 67.26 | S20: =IF(AND(ISNUMBER(Histórico!$A20),ISNUMBER(Histórico!D20),Histórico!D20>0),Histórico!D20,S19) -> 372.95 | T20: =IF(AND(ISNUMBER(Histórico!$A20),ISNUMBER(Histórico!E20),Histórico!E20>0),Histórico!E20,T19) -> 4.9859 | U20: =IF(ISNUMBER(Histórico!A20),Histórico!A20,U19) -> 46300
